#VRML_SIM R2020a utf8
WorldInfo {
  info [
    "Simulation of the KUKA youBot robot."
    "This model includes an accurate and fast simulation of the Meccanum wheels."
    "The robot can be equiped with various sensors (including the Microsoft Kinect) and configured with zero, one or two arms."
  ]
  title "KUKA youBot"
  basicTimeStep 16
  contactProperties [
    ContactProperties {
      material1 "InteriorWheelMat"
      coulombFriction [
        1.8, 0, 0.2
      ]
      frictionRotation -0.9648 0
      bounce 0
      forceDependentSlip [
        10, 0
      ]
    }
    ContactProperties {
      material1 "ExteriorWheelMat"
      coulombFriction [
        1.8, 0, 0.2
      ]
      frictionRotation 0.9648 0
      bounce 0
      forceDependentSlip [
        10, 0
      ]
    }
  ]
}
Viewpoint {
  orientation 0.3627126776605024 0.9010906234883417 0.23764511719313744 5.339092191123877
  position -0.4733890077296292 0.8641207556124572 4.728646042755178
  follow "None"
  followType "None"
}
Background {
  skyColor [
    1 1 1
  ]
}
DirectionalLight {
  direction 0 -1 0
  intensity 2.3
}
Floor {
  size 30 30
}
CerealBox {
  translation 1.87828 0.0499755 4.09981
  rotation 0.026117390829016672 0.026117390829016672 0.9993176490949055 1.57148
  name "cereal box(16)"
  textureUrl [
    "textures/cereal_box_1.jpg"
  ]
}
BiscuitBox {
  translation 1.0375 0.001421 3.92865
  rotation 1.92322e-08 1 -2.50203e-11 -1.5707953071795862
  name "biscuit box(5)"
  size 0.14 0.18 0.08
}
Floor {
  name "floor(6)"
  size 3 3
}
Floor {
  name "floor(7)"
  size 3 3
}
Floor {
  name "floor(5)"
  size 3 3
}
Floor {
  name "floor(3)"
  size 4 4
}
Floor {
  name "floor(4)"
  size 3 3
}
Floor {
  name "floor(2)"
  size 3 3
}
Floor {
  name "floor(1)"
  size 3 3
}
DEF SHELF1 Cabinet {
  translation -2.00631 0.00999986 -0.00808912
  rotation 6.64575e-11 1 -1.9239e-08 1.56423
  name "cabinet(4)"
  depth 0.3
  innerThickness 0.001
  outerThickness 0.001
  rowsHeights [
    0.2, 0.4
  ]
  columnsWidths [
    0.25, 0.25, 0.25, 0.25, 0.25, 0.25, 0.25, 0.25
  ]
  layout [
    "Shelf(1,2,8, 0)"
    "Shelf( 1, 1, 0, 1)"
    "Shelf(2, 1, 0, 1)"
    "Shelf( 3, 1, 0, 1)"
    "Shelf( 4, 1, 0, 1)"
    "Shelf( 5, 1, 0, 1)"
    "Shelf( 6, 1, 0, 1)"
    "Shelf( 7, 1, 0, 1)"
    "Shelf( 1, 2, 0, 1)"
    "Shelf( 2, 2, 0, 1)"
    "Shelf( 3, 2, 0, 1)"
    "Shelf(4, 2, 0, 1)"
    "Shelf(5, 2, 0, 1)"
    "Shelf(6, 2, 0, 1)"
    "Shelf(7, 2, 0, 1)"
  ]
  primaryAppearance PaintedWood {
    colorOverride 0.43529411764705883 0.3058823529411765 0.27450980392156865
  }
}
DEF SHELF2 Cabinet {
  translation 1.99373 0.00999986 -0.18975
  rotation -1.91133e-08 -1 -6.60232e-11 1.57736
  name "cabinet(2)"
  depth 0.3
  innerThickness 0.001
  outerThickness 0.001
  rowsHeights [
    0.2, 0.4
  ]
  columnsWidths [
    0.25, 0.25, 0.25, 0.25, 0.25, 0.25, 0.25, 0.25
  ]
  layout [
    "Shelf(1,2,8, 0)"
    "Shelf( 1, 1, 0, 1)"
    "Shelf(2, 1, 0, 1)"
    "Shelf( 3, 1, 0, 1)"
    "Shelf( 4, 1, 0, 1)"
    "Shelf( 5, 1, 0, 1)"
    "Shelf( 6, 1, 0, 1)"
    "Shelf( 7, 1, 0, 1)"
    "Shelf( 1, 2, 0, 1)"
    "Shelf( 2, 2, 0, 1)"
    "Shelf( 3, 2, 0, 1)"
    "Shelf(4, 2, 0, 1)"
    "Shelf(5, 2, 0, 1)"
    "Shelf(6, 2, 0, 1)"
    "Shelf(7, 2, 0, 1)"
  ]
  primaryAppearance PaintedWood {
    colorOverride 0.43529411764705883 0.3058823529411765 0.27450980392156865
  }
}
DEF SHELF3 Cabinet {
  translation -0.011952 0.01 -2.0091
  rotation 0 -1 0 2.63055e-06
  name "cabinet(3)"
  depth 0.3
  innerThickness 0.001
  outerThickness 0.001
  rowsHeights [
    0.4, 0.2
  ]
  columnsWidths [
    0.25, 0.25, 0.25, 0.25, 0.25, 0.25, 0.25, 0.25
  ]
  layout [
    "Shelf(1,2,8, 0)"
    "Shelf( 1, 1, 0, 1)"
    "Shelf(2, 1, 0, 1)"
    "Shelf( 3, 1, 0, 1)"
    "Shelf( 4, 1, 0, 1)"
    "Shelf( 5, 1, 0, 1)"
    "Shelf( 6, 1, 0, 1)"
    "Shelf( 7, 1, 0, 1)"
    "Shelf( 1, 2, 0, 1)"
    "Shelf( 2, 2, 0, 1)"
    "Shelf( 3, 2, 0, 1)"
    "Shelf(4, 2, 0, 1)"
    "Shelf(5, 2, 0, 1)"
    "Shelf(6, 2, 0, 1)"
    "Shelf(7, 2, 0, 1)"
  ]
  primaryAppearance PaintedWood {
    colorOverride 0.43529411764705883 0.3058823529411765 0.27450980392156865
  }
}
DEF SHELF4 Cabinet {
  translation 0.000310603 0.01 2.00944
  rotation -9.58636e-09 -1 -1.22918e-14 -3.1415853071795863
  name "cabinet(1)"
  depth 0.3
  innerThickness 0.001
  outerThickness 0.001
  rowsHeights [
    0.4, 0.4
  ]
  columnsWidths [
    0.25, 0.25, 0.25, 0.25, 0.25, 0.25, 0.25, 0.25
  ]
  layout [
    "Shelf(1,2,8, 0)"
    "Shelf( 1, 1, 0, 1)"
    "Shelf(2, 1, 0, 1)"
    "Shelf( 3, 1, 0, 1)"
    "Shelf( 4, 1, 0, 1)"
    "Shelf( 5, 1, 0, 1)"
    "Shelf( 6, 1, 0, 1)"
    "Shelf( 7, 1, 0, 1)"
    "Shelf( 1, 2, 0, 1)"
    "Shelf( 2, 2, 0, 1)"
    "Shelf( 3, 2, 0, 1)"
    "Shelf(4, 2, 0, 1)"
    "Shelf(5, 2, 0, 1)"
    "Shelf(6, 2, 0, 1)"
    "Shelf(7, 2, 0, 1)"
  ]
  primaryAppearance PaintedWood {
    colorOverride 0.43529411764705883 0.3058823529411765 0.27450980392156865
  }
}
DEF REPOSITORY Solid {
  translation -0.00197906 0.001 -0.00408673
  scale 5 5 5
  children [
    DEF repository Shape {
      appearance PBRAppearance {
        baseColor 0.792156862745098 0.6431372549019608 0.5686274509803921
        roughness 1
        metalness 0
      }
      geometry Box {
        size 0.25 0.0001 0.25
      }
    }
  ]
  name "solid(1)"
  boundingObject USE repository
}
DEF R1 Solid {
  translation -0.328584 0.035 -0.022816
  scale 4 4 4
  children [
    DEF r1 Shape {
      appearance PBRAppearance {
        baseColor 0.41568627450980394 0.28627450980392155 0.2549019607843137
        roughness 1
        metalness 0
      }
      geometry Box {
        size 0.15625 0.05 0.005
      }
    }
  ]
  name "solid(2)"
  boundingObject USE r1
}
DEF R2 Solid {
  translation -0.00070234 0.035 0.279833
  rotation 0 1 0 1.5707996938995747
  scale 4.2 4.2 4.2
  children [
    USE r1
  ]
  name "solid(4)"
  boundingObject USE r1
}
DEF R3 Solid {
  translation 0.31182 0.035 -0.00701387
  scale 4 4 4
  children [
    USE r1
  ]
  name "solid(3)"
  boundingObject USE r1
}
DEF R4 Solid {
  translation -0.00852162 0.035 -0.312751
  rotation 0 1 0 1.5707996938995747
  scale 4 4 4
  children [
    USE r1
  ]
  name "solid(5)"
  boundingObject USE r1
}
DEF SEU_SuperBot_Test Robot {
  translation 1.03232 0.0646674 4.39375
  rotation -0.5633156863306495 0.5842411477865237 0.5842411477865236 2.1155749025935027
  children [
    DEF GRIPPER_BASE Solid {
      translation 0.15 -1.19235e-07 0.08
      rotation 0.5773489358504745 -0.5773479358505856 -0.577353935849919 2.0944
      children [
        DEF LIFT_SLIDER SliderJoint {
          jointParameters JointParameters {
            axis 0 -1 0
          }
          device [
            LinearMotor {
              name "lift motor"
              minPosition -0.05
              maxPosition 0.05
            }
          ]
          endPoint DEF LIFT Solid {
            translation 0 0 -0.0425
            children [
              DEF LEFT_FINGER_SLIDER SliderJoint {
                jointParameters JointParameters {
                  axis -1 0 0
                }
                device [
                  LinearMotor {
                    name "left finger motor"
                    maxPosition 0.1
                  }
                ]
                endPoint DEF LEFT_FINGER Solid {
                  translation -0.022 0 -0.02
                  children [
                    Group {
                      children [
                        Transform {
                          translation 0 0.0015 -0.003
                          children [
                            Shape {
                              appearance DEF METAL_APPEARANCE PBRAppearance {
                                baseColorMap ImageTexture {
                                  url [
                                    "textures/metal.jpg"
                                  ]
                                }
                                roughness 0.2
                              }
                              geometry Box {
                                size 0.018 0.031 0.036
                              }
                            }
                          ]
                        }
                        DEF LEFT_FINGER_TRANSFORM Transform {
                          translation 0.0015 -0.006 -0.069
                          children [
                            Shape {
                              appearance DEF BLACK_APPEARANCE PBRAppearance {
                                baseColor 0.0705882 0.0705882 0.0705882
                                roughness 0.4
                                metalness 0
                              }
                              geometry Box {
                                size 0.015 0.035 0.095
                              }
                            }
                          ]
                        }
                      ]
                    }
                  ]
                  name "left finger"
                  boundingObject USE LEFT_FINGER_TRANSFORM
                  physics DEF LEFT_FINGER_PHYSICS Physics {
                  }
                }
              }
              DEF RIGHT_FINGER_SLIDER SliderJoint {
                jointParameters JointParameters {
                  axis 1 0 0
                }
                device [
                  LinearMotor {
                    name "right finger motor"
                    maxPosition 0.1
                  }
                ]
                endPoint DEF RIGHT_FINGER Solid {
                  translation 0.022 0 -0.02
                  children [
                    Group {
                      children [
                        Transform {
                          translation 0 0.0015 -0.003
                          children [
                            Shape {
                              appearance USE METAL_APPEARANCE
                              geometry Box {
                                size 0.018 0.031 0.036
                              }
                            }
                          ]
                        }
                        DEF RIGHT_FINGER_TRANSFORM Transform {
                          translation -0.0015 -0.006 -0.069
                          children [
                            Shape {
                              appearance USE BLACK_APPEARANCE
                              geometry Box {
                                size 0.015 0.035 0.095
                              }
                            }
                          ]
                        }
                      ]
                    }
                  ]
                  name "right finger"
                  boundingObject USE RIGHT_FINGER_TRANSFORM
                  physics USE LEFT_FINGER_PHYSICS
                }
              }
              Transform {
                translation 0 -0.126 0.135
                children [
                  Group {
                    children [
                      Transform {
                        translation 0 0.1478 -0.154
                        children [
                          DEF UPPER_BOX Shape {
                            appearance USE BLACK_APPEARANCE
                            geometry Box {
                              size 0.315 0.01 0.043419
                            }
                          }
                        ]
                      }
                      Transform {
                        translation 0 0.1072 -0.154
                        children [
                          USE UPPER_BOX
                        ]
                      }
                      Transform {
                        translation -0.155 0.1275 -0.154
                        children [
                          DEF LEFT_BOX Shape {
                            appearance USE BLACK_APPEARANCE
                            geometry Box {
                              size 0.007 0.05 0.042227
                            }
                          }
                        ]
                      }
                      Transform {
                        translation 0.155 0.1275 -0.154
                        children [
                          USE LEFT_BOX
                        ]
                      }
                      Transform {
                        translation 0 0.126 -0.158
                        children [
                          DEF CENTER_BOX Shape {
                            appearance USE BLACK_APPEARANCE
                            geometry Box {
                              size 0.027 0.0341 0.035
                            }
                          }
                        ]
                      }
                      Transform {
                        translation 0 0.132 -0.154
                        rotation 0 0 1 1.5708
                        children [
                          DEF UPPER_CYLINDER Shape {
                            appearance USE METAL_APPEARANCE
                            geometry Cylinder {
                              height 0.3
                              radius 0.00225
                            }
                          }
                        ]
                      }
                      Transform {
                        translation 0 0.118 -0.154
                        rotation 0 0 1 1.5708
                        children [
                          Shape {
                            appearance USE METAL_APPEARANCE
                            geometry Cylinder {
                              height 0.3
                              radius 0.00125
                            }
                          }
                        ]
                      }
                      Transform {
                        translation -0.041 0.155 -0.148
                        children [
                          Shape {
                            appearance USE BLACK_APPEARANCE
                            geometry Box {
                              size 0.0141907 0.006 0.04
                            }
                          }
                        ]
                      }
                      Transform {
                        translation -0.036 0.145 -0.116
                        children [
                          Shape {
                            appearance USE METAL_APPEARANCE
                            geometry Box {
                              size 0.027 0.03 0.03
                            }
                          }
                        ]
                      }
                      Transform {
                        translation 0.041 0.155 -0.148
                        children [
                          Shape {
                            appearance USE BLACK_APPEARANCE
                            geometry Box {
                              size 0.0141907 0.006 0.04
                            }
                          }
                        ]
                      }
                      Transform {
                        translation 0.036 0.145 -0.116
                        children [
                          Shape {
                            appearance USE METAL_APPEARANCE
                            geometry Box {
                              size 0.027 0.03 0.03
                            }
                          }
                        ]
                      }
                    ]
                  }
                ]
              }
            ]
            boundingObject Transform {
              translation 0 0.0015 -0.019
              children [
                Shape {
                  appearance USE METAL_APPEARANCE
                  geometry Box {
                    size 0.315 0.05 0.045
                  }
                }
              ]
            }
            physics DEF LIFT_PHYSICS Physics {
            }
          }
        }
        Transform {
          translation 0 -0.126 0.135
          children [
            DEF BASE_SHAPE_GROUP Group {
              children [
                Transform {
                  translation 0 0.176 -0.154
                  children [
                    DEF UPPER_BOX Shape {
                      appearance USE BLACK_APPEARANCE
                      geometry Box {
                        size 0.141092 0.0170038 0.043419
                      }
                    }
                  ]
                }
                Transform {
                  translation 0 0.075 -0.154
                  children [
                    USE UPPER_BOX
                  ]
                }
                Transform {
                  translation -0.06 0.126 -0.158
                  children [
                    DEF LEFT_BOX Shape {
                      appearance USE BLACK_APPEARANCE
                      geometry Box {
                        size 0.02 0.0875 0.035
                      }
                    }
                  ]
                }
                Transform {
                  translation 0.06 0.126 -0.158
                  children [
                    USE LEFT_BOX
                  ]
                }
                Transform {
                  translation 0 0.126 -0.158
                  children [
                    DEF CENTER_BOX Shape {
                      appearance USE BLACK_APPEARANCE
                      geometry Box {
                        size 0.044 0.1 0.0315
                      }
                    }
                  ]
                }
                Transform {
                  translation -0.037 0.126 -0.158
                  children [
                    DEF LEFT_CYLINDER Shape {
                      appearance USE METAL_APPEARANCE
                      geometry Cylinder {
                        height 0.1
                        radius 0.003
                      }
                    }
                  ]
                }
                Transform {
                  translation 0.037 0.126 -0.158
                  children [
                    USE LEFT_CYLINDER
                  ]
                }
              ]
            }
          ]
        }
      ]
      name "Pioneer3 gripper"
      model "Pioneer3 gripper"
      boundingObject Transform {
        translation 0 0 -0.019
        children [
          Box {
            size 0.141 0.117 0.043
          }
        ]
      }
      physics DEF BASE_PHYSICS Physics {
      }
    }
    DEF Body Shape {
      appearance PBRAppearance {
        baseColor 0.521569 0.521569 0.521569
        baseColorMap ImageTexture {
          url [
            "textures/texture_grid.png"
          ]
        }
        roughness 1
        metalness 0
      }
      geometry Box {
        size 0.4 0.25 0.035
      }
    }
    DEF WHEEL1 InteriorWheel {
      translation 0.133 -0.163 -0.015
      rotation 5.564400156955045e-17 1 3.8950801098685317e-16 3.003362244515542
      anchor 0.133 -0.163 -0.015
      name "wheel1"
      sensorName "wheel1sensor"
    }
    DEF WHEEL2 ExteriorWheel {
      translation 0.133 0.163 -0.015
      rotation -2.334798818480222e-16 1 -2.334798818480222e-16 1.5882963432307244
      anchor 0.133 0.163 -0.015
      name "wheel2"
      sensorName "wheel2sensor"
    }
    DEF WHEEL3 ExteriorWheel {
      translation -0.133 -0.163 -0.015
      rotation -2.3519109296722874e-16 1 -3.13588123956305e-16 1.573543010148268
      anchor -0.133 -0.163 -0.015
      name "wheel3"
      sensorName "wheel3sensor"
    }
    DEF WHEEL4 InteriorWheel {
      translation -0.133 0.163 -0.015
      rotation 0 0.9999999999999999 0 3.029999417195442
      anchor -0.133 0.163 -0.015
      name "wheel4"
      sensorName "wheel4sensor"
    }
  ]
  name "SuperBot(1)"
  boundingObject Box {
    size 0.4 0.25 0.035
  }
  physics Physics {
    density -1
    mass 22
    centerOfMass [
      0 0 0
    ]
  }
  controller "SuperBot_Controller1_1"
}
